try{
    const a = 10;
    a = 12;
}
catch(err){
    console.log(err);
}